<?xml version="1.0" encoding="utf-8"?>
<!-- This URDF was automatically created by SolidWorks to URDF Exporter! Originally created by Stephen Brawner (brawner@gmail.com)
     Commit Version: 1.6.0-4-g7f85cfe  Build Version: 1.6.7995.38578
     For more information, please see http://wiki.ros.org/sw_urdf_exporter -->
<robot name="minicobo_v1.4">

<!-- LINK -->
    <link name="world"/>

  <link name="Link0">
    <inertial>
      <origin xyz="-0.000169872459617813 -2.36448827889745E-08 0.0132846923173683"  rpy="0 0 0" />
      <mass value="3.76174" />
      <inertia ixx="0.000673719313504642" ixy="-1.30755705487849E-08" ixz="-1.3262407834936E-06" iyy="0.000666781851440875" iyz="-1.80735801539484E-11" izz="0.00123663316539255" />
    </inertial>
    <visual>
      <origin xyz="0 0 0" rpy="0 0 0" />
      <geometry>
        <mesh filename="package://minicobo_v14/meshes/Link0.dae" />
      </geometry>
      <material name="">
        <color rgba="1 1 1 1" />
      </material>
    </visual>
    <collision>
      <origin xyz="0 0 0" rpy="0 0 0" />
      <geometry>
        <mesh  filename="package://minicobo_v14/meshes/Link0.dae" />
      </geometry>
    </collision>
  </link>

  <link name="Link1">
    <inertial>
      <origin xyz="-1.99985037409469E-06 0.0134079971540169 -0.061631393869219" rpy="0 0 0" />
      <mass value="3.1571" />
      <inertia ixx="0.0128375469787325" ixy="2.28361925094216E-07" ixz="5.81760635898215E-08" iyy="0.0126762000445666" iyz="-0.00161037595218336" izz="0.00390574573183596" />
    </inertial>
    <visual>
      <origin xyz="0 0 0" rpy="0 0 0" />
      <geometry>
        <mesh filename="package://minicobo_v14/meshes/Link1.dae" />
      </geometry>
      <material
        name="">
        <color rgba="1 1 1 1" />
      </material>
    </visual>
    <collision>
      <origin xyz="0 0 0" rpy="0 0 0" />
      <geometry>
        <mesh  filename="package://minicobo_v14/meshes/Link1.dae" />
      </geometry>
    </collision>
  </link>

<link name="Link2">
    <inertial>
      <origin xyz="0.090613 -1.3771E-06 0.0043964"  rpy="0 0 0" />
      <mass value="1.0141" />
      <inertia ixx="0.0019174" ixy="6.2208E-07" ixz="0.0022687" iyy="0.0073149"  iyz="-3.3214E-07" izz="0.0064681" />
    </inertial>
    <visual>
      <origin xyz="0 0 0" rpy="0 0 0" />
      <geometry>
        <mesh filename="package://minicobo_v14/meshes/Link2.dae" />
      </geometry>
      <material name="">
        <color rgba="1 1 1 1" />
      </material>
    </visual>
    <collision>
      <origin xyz="0 0 0" rpy="0 0 0" />
      <geometry>
        <mesh filename="package://minicobo_v14/meshes/Link2.dae" />
      </geometry>
    </collision>
  </link>

<link name="Link3">
    <inertial>
      <origin xyz="-2.836E-07 0.042086 0.012428" rpy="0 0 0" />
      <mass  value="2.018" />
      <inertia ixx="0.0055107" ixy="2.2287E-08" ixz="-3.4784E-08" iyy="0.0017496" iyz="0.0005528" izz="0.0052708" />
    </inertial>
    <visual>
      <origin xyz="0 0 0" rpy="0 0 0" />
      <geometry>
        <mesh filename="package://minicobo_v14/meshes/Link3.dae" />
      </geometry>
      <material name="">
        <color rgba="1 1 1 1" />
      </material>
    </visual>
    <collision>
      <origin xyz="0 0 0" rpy="0 0 0" />
      <geometry>
        <mesh filename="package://minicobo_v14/meshes/Link3.dae" />
      </geometry>
    </collision>
  </link>

<link name="Link4">
    <inertial>
      <origin xyz="-5.23366787087349E-06 0.025945911865393 -0.0349284126752025" rpy="0 0 0" />
      <mass value="0.412340000009804" />
      <inertia ixx="0.000648308078586465" ixy="2.01279577389176E-08" ixz="-2.91846428270101E-08" iyy="0.000622438484108618" iyz="-0.000147788635079694" izz="0.000313549566736677" />
    </inertial>
    <visual>
      <origin xyz="0 0 0" rpy="0 0 0" />
      <geometry>
        <mesh filename="package://minicobo_v14/meshes/Link4.dae" />
      </geometry>
      <material name="">
        <color rgba="1 1 1 1" />
      </material>
    </visual>
    <collision>
      <origin xyz="0 0 0" rpy="0 0 0" />
      <geometry>
        <mesh filename="package://minicobo_v14/meshes/Link4.dae" />
      </geometry>
    </collision>
  </link>

<link name="Link5">
    <inertial>
      <origin xyz="8.7254E-06 0.044553 0.010268" rpy="0 0 0" />
      <mass  value="1.6793" />
      <inertia ixx="0.0040718" ixy="4.0506E-07"  ixz="1.0998E-07" iyy="0.0013014" iyz="0.00040116" izz="0.0039042" />
    </inertial>
    <visual>
      <origin xyz="0 0 0" rpy="0 0 0" />
      <geometry>
        <mesh filename="package://minicobo_v14/meshes/Link5.dae" />
      </geometry>
      <material name="">
        <color rgba="1 1 1 1" />
      </material>
    </visual>
    <collision>
      <origin xyz="0 0 0" rpy="0 0 0" />
      <geometry>
        <mesh filename="package://minicobo_v14/meshes/Link5.dae" />
      </geometry>
    </collision>
  </link>

<link name="Link6">
    <inertial>
      <origin xyz="-2.33954680956047E-05 3.42676856690269E-05 -0.0202928698270544" rpy="0 0 0" />
      <mass value="0.311970001247665" />
      <inertia ixx="0.00014377819366" ixy="-8.50913479195225E-07"  ixz="-2.37501745813128E-07"  iyy="0.000142682702873271"  iyz="-3.26920852568197E-08" izz="0.000221812602025683" />
    </inertial>
    <visual>
      <origin xyz="0 0 0"  rpy="0 0 0" />
      <geometry>
        <mesh  filename="package://minicobo_v14/meshes/Link6.dae" />
      </geometry>
      <material name="">
        <color rgba="1 1 1 1" />
      </material>
    </visual>
    <collision>
      <origin xyz="0 0 0" rpy="0 0 0" />
      <geometry>
        <mesh filename="package://minicobo_v14/meshes/Link6.dae" />
      </geometry>
    </collision>
  </link>

<link name="dummy_tcp"/>


  <!-- JOINT -->

    <joint name="world_joint" type="fixed">
        <origin xyz="-0.25 0 0.75" rpy="0 2.5 0" />
        <parent link="world"/>
        <child link="Link0"/>
    </joint>

  <joint name="Joint1" type="revolute">
    <origin xyz="0 0 0.187" rpy="0 0 0" />
    <parent link="Link0" />
    <child link="Link1" />
    <axis xyz="0 0 1" />
    <limit lower="-6.28" upper="6.28"  effort="100" velocity="1.57" />
  </joint>

  <joint  name="Joint2" type="revolute">
    <origin xyz="0 -0.006 0" rpy="1.5708 -1.5708 0" />
    <parent  link="Link1" />
    <child link="Link2" />
    <axis xyz="0 0 1" />
    <limit lower="-2.09" upper="2.09" effort="100" velocity="1.57" />
  </joint>

  <joint  name="Joint3" type="revolute">
    <origin xyz="0.21 0 0" rpy="0 0 -1.5708" />
    <parent link="Link2" />
    <child link="Link3" />
    <axis xyz="0 0 1" />
    <limit lower="-2.27" upper="2.27" effort="100" velocity="1.57" />
  </joint>

  <joint name="Joint4" type="revolute">
    <origin xyz="0 0.2105 0" rpy="-1.5708 0 0" />
    <parent link="Link3" />
    <child link="Link4" />
    <axis xyz="0 0 1" />
    <limit lower="-6.28" upper="6.28" effort="100" velocity="1.57" />
  </joint>

  <joint name="Joint5" type="revolute">
    <origin xyz="0 0 0" rpy="1.5708 0 0" />
    <parent link="Link4" />
    <child link="Link5" />
    <axis xyz="0 0 1" />
    <limit lower="-2.09" upper="2.09" effort="100" velocity="1.57" />
  </joint>

  <joint name="Joint6" type="revolute">
    <origin xyz="0 0.1593 0" rpy="-1.5708 0 0" />
    <parent  link="Link5" />
    <child link="Link6" />
    <axis xyz="0 0 1" />
    <limit lower="-6.28" upper="6.28" effort="100" velocity="1.57" />
  </joint>

  <joint name="dummy_tcp_joint" type="fixed">
        <origin xyz="0 0 0" rpy="0 0 0" />
        <parent link="Link6" />
        <child link="dummy_tcp" />
  </joint>
  <link name="tool0"/>
  <joint name="flange-tool0" type="fixed">
    <!-- default toolframe - X+ left, Y+ up, Z+ front -->
    <origin rpy="1.5707963267948966 0 1.5707963267948966" xyz="0 0 0"/>
    <parent link="dummy-tcp"/>
    <child link="tool0"/>
  </joint>

</robot>